Workbook

Sheet 사용법
B1: 사후평가 운영 관리표 (2주 · 350명)
B2: 한 사람 = 한 줄. 번호 하나로 접수 → 운동평가 → 혈압·혈당 → 선생님 상담 → 추가상담까지 따라가며, 각 담당자는 자기 칸에 O만 선택합니다.
B4: 1. 시트 구성
B5: 현황판 | C5: 오늘 단계별 대기 인원, 전체 진행률, 일별 예약·완료 그래프, 구간별 평균 소요시간(병목 구간)
B6: 명단 | C6: 핵심 시트. 400줄(350명 + 여유). 번호(001~)로 찾아 입력. 맨 위 필터로 '오늘 예약자', '추가상담 대기' 등을 골라 봅니다.
B7: 일정표 | C7: 날짜 × 시간대 예약 인원. 정원 초과는 빨간색. 하루 정원 합계와 예약·완료·불참을 한눈에.
B8: 병목계산 | C8: 단계별 소요시간·담당 인원 → 하루 처리 가능 인원과 필요한 인력. 일정 짜기 전에 먼저 돌려 보세요.
B9: 설정 | C9: 목표 인원, 운영일, 시간대·정원, 혈압·혈당 판정 기준
B11: 2. 색 규칙
B12: 노란 칸 + 파란 글씨 | C12: 직접 입력·수정하는 설정값. 들어 있는 숫자는 모두 예시이니 실제 값으로 바꾸세요.
B13: 회색 칸 | C13: 자동 계산. 건드리지 마세요(수식이 지워집니다).
B14: 흰 칸 | C14: 명단에 직접 입력하는 칸
B15: 빨강 / 주황 / 초록 | C15: 빨강 = 긴급·정원 초과 · 주황 = 주의·추가상담 대기 · 초록 = 완료·O 입력됨
B17: 3. 시작 전 준비 (방문 1~2주 전)
B18: ① 설정 | C18: 목표 인원, 운영일, 시간대·정원 입력
B19: ② 병목계산 | C19: 단계별 1인당 소요분·담당 인원 입력 → '하루 처리 가능(명)'이 '하루 목표 인원'보다 작은 단계에 인력 추가 또는 정원 축소
B20: ③ 명단 | C20: 번호·이름·성별·연령·연락처·예약일·예약시간·특이사항(보행보조·청력·시력 등) 입력. 예약일·시간은 목록에서 선택
B21: ④ 일정표 | C21: 빨간 칸(정원 초과)을 다른 슬롯으로 조정. 불참 대비 예비일 1~2일 확보
B22: ⑤ 이름표·여정카드 | C22: '번호'를 큰 글씨로 인쇄(어르신 성함은 김·이·박 동명이인이 많아 번호가 기준). 카드에는 접수→운동→측정→상담 순서와 도장 칸
B24: 4. 당일 입력 방법 (담당자별)
B25: 접수 담당 | C25: 번호로 찾아 '접수'에 O. 예약일이 오늘이 아니면 예약일을 오늘로 고치세요(현황판은 예약일 기준 집계).
B26: 운동평가 담당 | C26: 평가 후 '운동평가 완료'에 O
B27: 간호실습생 | C27: 수축기·이완기·혈당 입력, 혈당조건(공복/식후) 선택. 측정 거부·불가면 해당 칸에 - 입력. '긴급'이 뜨면 즉시 선생님 호출.
B28: 선생님 | C28: 상담 후 '선생님 상담 완료'에 O. 추가상담이 필요하면 '추가상담 요청'에도 O (혈압·혈당 '긴급'은 자동으로 대상)
B29: 추가상담 담당 | C29: 상담 끝나면 '추가상담 완료'에 O → 진행 단계가 '완료'로 바뀜
B30: 현황 담당 | C30: 현황판의 '대기' 숫자를 보고 대기가 몰린 단계로 안내 인원을 보내거나 인력을 이동
B32: 5. 하루 마감 루틴 (10분)
B33: ① 현황판 | C33: 오늘 완료/미완료, 합계 확인이 OK인지 확인
B34: ② 명단 필터 | C34: 예약일 = 오늘, 진행 단계 = 미방문·불참·연기 → 재예약 연락 후 예약일·시간 수정, 불참/연기 칸 비우기
B35: ③ 다음 날 준비 | C35: '추가상담 대기'가 남았으면 다음 날 우선 배정 · 내일 예약자 필터로 확인 문자/전화 대상 확정
B36: ④ 백업 | C36: 파일을 날짜를 붙여 사본 저장(엑셀) 또는 구글 시트 버전 기록 확인
B38: 6. 입력 예시 (명단 한 줄)
B39: 번호 / 이름 / 성별 / 연령 | C39: 1 / 홍길동(가명) / 여 / 72
B40: 연락처 / 예약일 / 예약시간 | C40: 010-0000-0000 / 2026-10-19 / 09:00
B41: 특이사항 | C41: 지팡이 보행, 왼쪽 귀 난청(큰 소리로 안내)
B42: 접수 / 운동평가 완료 | C42: O / O
B43: 수축기 / 이완기 / 혈당 / 혈당조건 | C43: 128 / 76 / 104 / 공복
B44: 선생님 상담 완료 | C44: O → 진행 단계 '완료' 자동 표시
B45: 메모 | C45: 오른쪽 무릎 통증 호소, 다음 주 재방문 희망
B47: 7. 개인정보·보안 (중요)
...

Sheet 현황판
B1: 사후평가 현황판
B2: 명단에 O를 입력하면 자동으로 갱신됩니다. 아래 숫자는 직접 고치지 마세요.
B4: 기준일(오늘) | C4: =TODAY() -> 46307 | E4: 다른 날짜를 보려면 C4에 날짜를 직접 입력하세요.
B6: 오늘 현황 (예약일 = 기준일) | E6: 전체 진행 (목표 대비)
B7: 오늘 예약 인원 | C7: =COUNTIFS(명단!$F$5:$F$404,$C$4) -> 0 | E7: 목표 인원 | F7: =설정!C4 -> 350
B8: 아직 도착 전(미방문) | C8: =COUNTIFS(명단!$F$5:$F$404,$C$4,명단!$W$5:$W$404,"미방문") -> 0 | E8: 명단 등록 인원 | F8: =COUNTA(명단!$B$5:$B$404) -> 0
B9: 운동평가 대기 | C9: =COUNTIFS(명단!$F$5:$F$404,$C$4,명단!$W$5:$W$404,"운동평가 대기") -> 0 | E9: 완료 인원 | F9: =COUNTIF(명단!$W$5:$W$404,"완료") -> 0
B10: 혈압·혈당 측정 대기 | C10: =COUNTIFS(명단!$F$5:$F$404,$C$4,명단!$W$5:$W$404,"측정 대기") -> 0 | E10: 진행률 | F10: =IFERROR(F9/F7,0) -> 0
B11: 선생님 상담 대기 | C11: =COUNTIFS(명단!$F$5:$F$404,$C$4,명단!$W$5:$W$404,"상담 대기") -> 0 | E11: 남은 인원 | F11: =MAX(F7-F9,0) -> 350
B12: 추가상담 대기 | C12: =COUNTIFS(명단!$F$5:$F$404,$C$4,명단!$W$5:$W$404,"추가상담 대기") -> 0 | E12: 남은 운영일(기준일 포함) | F12: =COUNTIF(설정!C19:C28,">="&C4) -> 10
B13: 완료 | C13: =COUNTIFS(명단!$F$5:$F$404,$C$4,명단!$W$5:$W$404,"완료") -> 0 | E13: 남은 일수 기준 하루 필요 인원 | F13: =IF(F12=0,"-",ROUNDUP(F11/F12,0)) -> 35
B14: 불참·연기 | C14: =COUNTIFS(명단!$F$5:$F$404,$C$4,명단!$W$5:$W$404,"불참")+COUNTIFS(명단!$F$5:$F$404,$C$4,명단!$W$5:$W$404,"연기") -> 0 | E14: 불참·연기(재예약 필요) | F14: =COUNTIF(명단!$W$5:$W$404,"불참")+COUNTIF(명단!$W$5:$W$404,"연기") -> 0
B15: 현재 현장 체류 인원(대기 합) | C15: =SUM(C9:C12) -> 0 | E15: 추가상담 대상 / 이 중 대기 | F15: =COUNTIF(명단!$V$5:$V$404,"대상")&" / "&COUNTIF(명단!$W$5:$W$404,"추가상담 대기") -> 0 / 0
B16: 합계 확인 | C16: =IF(SUM(C8:C14)=C7,"OK","불일치: 예약일/상태 확인") -> OK
B19: 측정 결과 플래그 (누적) | E19: 구간별 평균 소요시간 (분, 대기 포함)
B20: 혈압 긴급 (즉시 선생님 호출) | C20: =COUNTIF(명단!$T$5:$T$404,"긴급") -> 0 | E20: 접수 → 운동평가 완료 | F20: =IFERROR(ROUND(AVERAGE(명단!$AC$5:$AC$404),0),"-") -> -
B21: 혈압 주의 | C21: =COUNTIF(명단!$T$5:$T$404,"주의") -> 0 | E21: 운동평가 → 측정 완료 | F21: =IFERROR(ROUND(AVERAGE(명단!$AD$5:$AD$404),0),"-") -> -
B22: 혈당 긴급 | C22: =SUMPRODUCT(--(LEFT(명단!$U$5:$U$404,2)="긴급")) -> 0 | E22: 측정 → 상담 완료 | F22: =IFERROR(ROUND(AVERAGE(명단!$AE$5:$AE$404),0),"-") -> -
B23: 혈당 주의 | C23: =COUNTIF(명단!$U$5:$U$404,"주의") -> 0 | E23: 상담 → 추가상담 완료 | F23: =IFERROR(ROUND(AVERAGE(명단!$AF$5:$AF$404),0),"-") -> -
B24: 혈당조건(공복/식후) 미기록 | C24: =COUNTIF(명단!$U$5:$U$404,"조건확인") -> 0 | E24: 접수 → 최종 완료 (전체) | F24: =IFERROR(ROUND(AVERAGE(명단!$AG$5:$AG$404),0),"-") -> -
E25: 가장 오래 걸리는 구간 | F25: =IFERROR(INDEX(E20:E23,MATCH(MAX(F20:F23),F20:F23,0)),"-") -> -
E26: ※ 시각 기록(명단 X~AB열)이 있어야 계산됩니다. 없으면 '-'.

Sheet 명단
A1: 명단 (한 사람 = 한 줄 · 번호로 찾기)
A2: 흰 칸에 입력, 회색 칸은 자동 계산(수정 금지). 단계가 끝나면 해당 칸에 O 선택. 측정 거부·불가 시 해당 칸에 - 입력.
A3: 기본 정보 (사전 입력) | I3: 접수·운동평가 | K3: 혈압·혈당 (간호실습생) | O3: 상담 | R3: 기타 | T3: 자동 계산 | X3: 단계별 시각 (스크립트 사용 시 자동) | AC3: 구간 소요시간 (분, 대기 포함)
A4: 번호 | B4: 이름 | C4: 성별 | D4: 연령 | E4: 연락처 | F4: 예약일 | G4: 예약시간 | H4: 특이사항 | I4: 접수 | J4: 운동평가 완료 | K4: 수축기 | L4: 이완기 | M4: 혈당 | N4: 혈당조건 | O4: 선생님 상담 완료 | P4: 추가상담 요청 | Q4: 추가상담 완료 | R4: 불참/연기 | S4: 메모 | T4: 혈압 판정 | U4: 혈당 판정 | V4: 추가상담 대상 | W4: 진행 단계 | X4: 접수 시각 | Y4: 운동평가 시각 | Z4: 측정 시각 | AA4: 상담 시각 | AB4: 추가상담 시각 | AC4: 접수→운동평가(분) | AD4: 운동평가→측정(분) | AE4: 측정→상담(분) | AF4: 상담→추가상담(분) | AG4: 접수→최종완료(분)
A5: 1 | T5: =IF(AND(K5="",L5=""),"",IF(OR(K5="-",L5="-"),"측정불가",IF(AND(ISNUMBER(K5),ISNUMBER(L5)),IF(OR(K5>=설정!$C$9,L5>=설정!$C$10),"긴급",IF(OR(K5>=설정!$C$7,L5>=설정!$C$8,K5<설정!$C$11),"주의","정상")),"확인필요"))) | U5: =IF(M5="","",IF(M5="-","측정불가",IF(NOT(ISNUMBER(M5)),"확인필요",IF(M5<설정!$C$15,"긴급(저혈당)",IF(M5>=설정!$C$16,"긴급(고혈당)",IF(N5="공복",IF(M5>=설정!$C$13,"주의","정상"),IF(N5="식후",IF(M5>=설정!$C$14,"주의","정상"),"조건확인"))))))) | V5: =IF(OR(T5="긴급",LEFT(U5,2)="긴급",P5="O"),"대상","") | W5: =IF(R5<>"",R5,IF(O5="O",IF(V5="대상",IF(Q5="O","완료","추가상담 대기"),"완료"),IF(COUNTA(K5:M5)=3,"상담 대기",IF(J5="O","측정 대기",IF(I5="O","운동평가 대기","미방문"))))) -> 미방문 | AC5: =IF(AND(ISNUMBER(X5),ISNUMBER(Y5)),IF(Y5>=X5,ROUND((Y5-X5)*1440,0),""),"") | AD5: =IF(AND(ISNUMBER(Y5),ISNUMBER(Z5)),IF(Z5>=Y5,ROUND((Z5-Y5)*1440,0),""),"") | AE5: =IF(AND(ISNUMBER(Z5),ISNUMBER(AA5)),IF(AA5>=Z5,ROUND((AA5-Z5)*1440,0),""),"") | AF5: =IF(AND(ISNUMBER(AA5),ISNUMBER(AB5)),IF(AB5>=AA5,ROUND((AB5-AA5)*1440,0),""),"") | AG5: =IF(AND(W5="완료",ISNUMBER(X5)),IF(MAX(Y5:AB5)>=X5,ROUND((MAX(Y5:AB5)-X5)*1440,0),""),"")
A6: 2 | T6: =IF(AND(K6="",L6=""),"",IF(OR(K6="-",L6="-"),"측정불가",IF(AND(ISNUMBER(K6),ISNUMBER(L6)),IF(OR(K6>=설정!$C$9,L6>=설정!$C$10),"긴급",IF(OR(K6>=설정!$C$7,L6>=설정!$C$8,K6<설정!$C$11),"주의","정상")),"확인필요"))) | U6: =IF(M6="","",IF(M6="-","측정불가",IF(NOT(ISNUMBER(M6)),"확인필요",IF(M6<설정!$C$15,"긴급(저혈당)",IF(M6>=설정!$C$16,"긴급(고혈당)",IF(N6="공복",IF(M6>=설정!$C$13,"주의","정상"),IF(N6="식후",IF(M6>=설정!$C$14,"주의","정상"),"조건확인"))))))) | V6: =IF(OR(T6="긴급",LEFT(U6,2)="긴급",P6="O"),"대상","") | W6: =IF(R6<>"",R6,IF(O6="O",IF(V6="대상",IF(Q6="O","완료","추가상담 대기"),"완료"),IF(COUNTA(K6:M6)=3,"상담 대기",IF(J6="O","측정 대기",IF(I6="O","운동평가 대기","미방문"))))) -> 미방문 | AC6: =IF(AND(ISNUMBER(X6),ISNUMBER(Y6)),IF(Y6>=X6,ROUND((Y6-X6)*1440,0),""),"") | AD6: =IF(AND(ISNUMBER(Y6),ISNUMBER(Z6)),IF(Z6>=Y6,ROUND((Z6-Y6)*1440,0),""),"") | AE6: =IF(AND(ISNUMBER(Z6),ISNUMBER(AA6)),IF(AA6>=Z6,ROUND((AA6-Z6)*1440,0),""),"") | AF6: =IF(AND(ISNUMBER(AA6),ISNUMBER(AB6)),IF(AB6>=AA6,ROUND((AB6-AA6)*1440,0),""),"") | AG6: =IF(AND(W6="완료",ISNUMBER(X6)),IF(MAX(Y6:AB6)>=X6,ROUND((MAX(Y6:AB6)-X6)*1440,0),""),"")
A7: 3 | T7: =IF(AND(K7="",L7=""),"",IF(OR(K7="-",L7="-"),"측정불가",IF(AND(ISNUMBER(K7),ISNUMBER(L7)),IF(OR(K7>=설정!$C$9,L7>=설정!$C$10),"긴급",IF(OR(K7>=설정!$C$7,L7>=설정!$C$8,K7<설정!$C$11),"주의","정상")),"확인필요"))) | U7: =IF(M7="","",IF(M7="-","측정불가",IF(NOT(ISNUMBER(M7)),"확인필요",IF(M7<설정!$C$15,"긴급(저혈당)",IF(M7>=설정!$C$16,"긴급(고혈당)",IF(N7="공복",IF(M7>=설정!$C$13,"주의","정상"),IF(N7="식후",IF(M7>=설정!$C$14,"주의","정상"),"조건확인"))))))) | V7: =IF(OR(T7="긴급",LEFT(U7,2)="긴급",P7="O"),"대상","") | W7: =IF(R7<>"",R7,IF(O7="O",IF(V7="대상",IF(Q7="O","완료","추가상담 대기"),"완료"),IF(COUNTA(K7:M7)=3,"상담 대기",IF(J7="O","측정 대기",IF(I7="O","운동평가 대기","미방문"))))) -> 미방문 | AC7: =IF(AND(ISNUMBER(X7),ISNUMBER(Y7)),IF(Y7>=X7,ROUND((Y7-X7)*1440,0),""),"") | AD7: =IF(AND(ISNUMBER(Y7),ISNUMBER(Z7)),IF(Z7>=Y7,ROUND((Z7-Y7)*1440,0),""),"") | AE7: =IF(AND(ISNUMBER(Z7),ISNUMBER(AA7)),IF(AA7>=Z7,ROUND((AA7-Z7)*1440,0),""),"") | AF7: =IF(AND(ISNUMBER(AA7),ISNUMBER(AB7)),IF(AB7>=AA7,ROUND((AB7-AA7)*1440,0),""),"") | AG7: =IF(AND(W7="완료",ISNUMBER(X7)),IF(MAX(Y7:AB7)>=X7,ROUND((MAX(Y7:AB7)-X7)*1440,0),""),"")
A8: 4 | T8: =IF(AND(K8="",L8=""),"",IF(OR(K8="-",L8="-"),"측정불가",IF(AND(ISNUMBER(K8),ISNUMBER(L8)),IF(OR(K8>=설정!$C$9,L8>=설정!$C$10),"긴급",IF(OR(K8>=설정!$C$7,L8>=설정!$C$8,K8<설정!$C$11),"주의","정상")),"확인필요"))) | U8: =IF(M8="","",IF(M8="-","측정불가",IF(NOT(ISNUMBER(M8)),"확인필요",IF(M8<설정!$C$15,"긴급(저혈당)",IF(M8>=설정!$C$16,"긴급(고혈당)",IF(N8="공복",IF(M8>=설정!$C$13,"주의","정상"),IF(N8="식후",IF(M8>=설정!$C$14,"주의","정상"),"조건확인"))))))) | V8: =IF(OR(T8="긴급",LEFT(U8,2)="긴급",P8="O"),"대상","") | W8: =IF(R8<>"",R8,IF(O8="O",IF(V8="대상",IF(Q8="O","완료","추가상담 대기"),"완료"),IF(COUNTA(K8:M8)=3,"상담 대기",IF(J8="O","측정 대기",IF(I8="O","운동평가 대기","미방문"))))) -> 미방문 | AC8: =IF(AND(ISNUMBER(X8),ISNUMBER(Y8)),IF(Y8>=X8,ROUND((Y8-X8)*1440,0),""),"") | AD8: =IF(AND(ISNUMBER(Y8),ISNUMBER(Z8)),IF(Z8>=Y8,ROUND((Z8-Y8)*1440,0),""),"") | AE8: =IF(AND(ISNUMBER(Z8),ISNUMBER(AA8)),IF(AA8>=Z8,ROUND((AA8-Z8)*1440,0),""),"") | AF8: =IF(AND(ISNUMBER(AA8),ISNUMBER(AB8)),IF(AB8>=AA8,ROUND((AB8-AA8)*1440,0),""),"") | AG8: =IF(AND(W8="완료",ISNUMBER(X8)),IF(MAX(Y8:AB8)>=X8,ROUND((MAX(Y8:AB8)-X8)*1440,0),""),"")
A9: 5 | T9: =IF(AND(K9="",L9=""),"",IF(OR(K9="-",L9="-"),"측정불가",IF(AND(ISNUMBER(K9),ISNUMBER(L9)),IF(OR(K9>=설정!$C$9,L9>=설정!$C$10),"긴급",IF(OR(K9>=설정!$C$7,L9>=설정!$C$8,K9<설정!$C$11),"주의","정상")),"확인필요"))) | U9: =IF(M9="","",IF(M9="-","측정불가",IF(NOT(ISNUMBER(M9)),"확인필요",IF(M9<설정!$C$15,"긴급(저혈당)",IF(M9>=설정!$C$16,"긴급(고혈당)",IF(N9="공복",IF(M9>=설정!$C$13,"주의","정상"),IF(N9="식후",IF(M9>=설정!$C$14,"주의","정상"),"조건확인"))))))) | V9: =IF(OR(T9="긴급",LEFT(U9,2)="긴급",P9="O"),"대상","") | W9: =IF(R9<>"",R9,IF(O9="O",IF(V9="대상",IF(Q9="O","완료","추가상담 대기"),"완료"),IF(COUNTA(K9:M9)=3,"상담 대기",IF(J9="O","측정 대기",IF(I9="O","운동평가 대기","미방문"))))) -> 미방문 | AC9: =IF(AND(ISNUMBER(X9),ISNUMBER(Y9)),IF(Y9>=X9,ROUND((Y9-X9)*1440,0),""),"") | AD9: =IF(AND(ISNUMBER(Y9),ISNUMBER(Z9)),IF(Z9>=Y9,ROUND((Z9-Y9)*1440,0),""),"") | AE9: =IF(AND(ISNUMBER(Z9),ISNUMBER(AA9)),IF(AA9>=Z9,ROUND((AA9-Z9)*1440,0),""),"") | AF9: =IF(AND(ISNUMBER(AA9),ISNUMBER(AB9)),IF(AB9>=AA9,ROUND((AB9-AA9)*1440,0),""),"") | AG9: =IF(AND(W9="완료",ISNUMBER(X9)),IF(MAX(Y9:AB9)>=X9,ROUND((MAX(Y9:AB9)-X9)*1440,0),""),"")
A10: 6 | T10: =IF(AND(K10="",L10=""),"",IF(OR(K10="-",L10="-"),"측정불가",IF(AND(ISNUMBER(K10),ISNUMBER(L10)),IF(OR(K10>=설정!$C$9,L10>=설정!$C$10),"긴급",IF(OR(K10>=설정!$C$7,L10>=설정!$C$8,K10<설정!$C$11),"주의","정상")),"확인필요"))) | U10: =IF(M10="","",IF(M10="-","측정불가",IF(NOT(ISNUMBER(M10)),"확인필요",IF(M10<설정!$C$15,"긴급(저혈당)",IF(M10>=설정!$C$16,"긴급(고혈당)",IF(N10="공복",IF(M10>=설정!$C$13,"주의","정상"),IF(N10="식후",IF(M10>=설정!$C$14,"주의","정상"),"조건확인"))))))) | V10: =IF(OR(T10="긴급",LEFT(U10,2)="긴급",P10="O"),"대상","") | W10: =IF(R10<>"",R10,IF(O10="O",IF(V10="대상",IF(Q10="O","완료","추가상담 대기"),"완료"),IF(COUNTA(K10:M10)=3,"상담 대기",IF(J10="O","측정 대기",IF(I10="O","운동평가 대기","미방문"))))) -> 미방문 | AC10: =IF(AND(ISNUMBER(X10),ISNUMBER(Y10)),IF(Y10>=X10,ROUND((Y10-X10)*1440,0),""),"") | AD10: =IF(AND(ISNUMBER(Y10),ISNUMBER(Z10)),IF(Z10>=Y10,ROUND((Z10-Y10)*1440,0),""),"") | AE10: =IF(AND(ISNUMBER(Z10),ISNUMBER(AA10)),IF(AA10>=Z10,ROUND((AA10-Z10)*1440,0),""),"") | AF10: =IF(AND(ISNUMBER(AA10),ISNUMBER(AB10)),IF(AB10>=AA10,ROUND((AB10-AA10)*1440,0),""),"") | AG10: =IF(AND(W10="완료",ISNUMBER(X10)),IF(MAX(Y10:AB10)>=X10,ROUND((MAX(Y10:AB10)-X10)*1440,0),""),"")
A11: 7 | T11: =IF(AND(K11="",L11=""),"",IF(OR(K11="-",L11="-"),"측정불가",IF(AND(ISNUMBER(K11),ISNUMBER(L11)),IF(OR(K11>=설정!$C$9,L11>=설정!$C$10),"긴급",IF(OR(K11>=설정!$C$7,L11>=설정!$C$8,K11<설정!$C$11),"주의","정상")),"확인필요"))) | U11: =IF(M11="","",IF(M11="-","측정불가",IF(NOT(ISNUMBER(M11)),"확인필요",IF(M11<설정!$C$15,"긴급(저혈당)",IF(M11>=설정!$C$16,"긴급(고혈당)",IF(N11="공복",IF(M11>=설정!$C$13,"주의","정상"),IF(N11="식후",IF(M11>=설정!$C$14,"주의","정상"),"조건확인"))))))) | V11: =IF(OR(T11="긴급",LEFT(U11,2)="긴급",P11="O"),"대상","") | W11: =IF(R11<>"",R11,IF(O11="O",IF(V11="대상",IF(Q11="O","완료","추가상담 대기"),"완료"),IF(COUNTA(K11:M11)=3,"상담 대기",IF(J11="O","측정 대기",IF(I11="O","운동평가 대기","미방문"))))) -> 미방문 | AC11: =IF(AND(ISNUMBER(X11),ISNUMBER(Y11)),IF(Y11>=X11,ROUND((Y11-X11)*1440,0),""),"") | AD11: =IF(AND(ISNUMBER(Y11),ISNUMBER(Z11)),IF(Z11>=Y11,ROUND((Z11-Y11)*1440,0),""),"") | AE11: =IF(AND(ISNUMBER(Z11),ISNUMBER(AA11)),IF(AA11>=Z11,ROUND((AA11-Z11)*1440,0),""),"") | AF11: =IF(AND(ISNUMBER(AA11),ISNUMBER(AB11)),IF(AB11>=AA11,ROUND((AB11-AA11)*1440,0),""),"") | AG11: =IF(AND(W11="완료",ISNUMBER(X11)),IF(MAX(Y11:AB11)>=X11,ROUND((MAX(Y11:AB11)-X11)*1440,0),""),"")
A12: 8 | T12: =IF(AND(K12="",L12=""),"",IF(OR(K12="-",L12="-"),"측정불가",IF(AND(ISNUMBER(K12),ISNUMBER(L12)),IF(OR(K12>=설정!$C$9,L12>=설정!$C$10),"긴급",IF(OR(K12>=설정!$C$7,L12>=설정!$C$8,K12<설정!$C$11),"주의","정상")),"확인필요"))) | U12: =IF(M12="","",IF(M12="-","측정불가",IF(NOT(ISNUMBER(M12)),"확인필요",IF(M12<설정!$C$15,"긴급(저혈당)",IF(M12>=설정!$C$16,"긴급(고혈당)",IF(N12="공복",IF(M12>=설정!$C$13,"주의","정상"),IF(N12="식후",IF(M12>=설정!$C$14,"주의","정상"),"조건확인"))))))) | V12: =IF(OR(T12="긴급",LEFT(U12,2)="긴급",P12="O"),"대상","") | W12: =IF(R12<>"",R12,IF(O12="O",IF(V12="대상",IF(Q12="O","완료","추가상담 대기"),"완료"),IF(COUNTA(K12:M12)=3,"상담 대기",IF(J12="O","측정 대기",IF(I12="O","운동평가 대기","미방문"))))) -> 미방문 | AC12: =IF(AND(ISNUMBER(X12),ISNUMBER(Y12)),IF(Y12>=X12,ROUND((Y12-X12)*1440,0),""),"") | AD12: =IF(AND(ISNUMBER(Y12),ISNUMBER(Z12)),IF(Z12>=Y12,ROUND((Z12-Y12)*1440,0),""),"") | AE12: =IF(AND(ISNUMBER(Z12),ISNUMBER(AA12)),IF(AA12>=Z12,ROUND((AA12-Z12)*1440,0),""),"") | AF12: =IF(AND(ISNUMBER(AA12),ISNUMBER(AB12)),IF(AB12>=AA12,ROUND((AB12-AA12)*1440,0),""),"") | AG12: =IF(AND(W12="완료",ISNUMBER(X12)),IF(MAX(Y12:AB12)>=X12,ROUND((MAX(Y12:AB12)-X12)*1440,0),""),"")
A13: 9 | T13: =IF(AND(K13="",L13=""),"",IF(OR(K13="-",L13="-"),"측정불가",IF(AND(ISNUMBER(K13),ISNUMBER(L13)),IF(OR(K13>=설정!$C$9,L13>=설정!$C$10),"긴급",IF(OR(K13>=설정!$C$7,L13>=설정!$C$8,K13<설정!$C$11),"주의","정상")),"확인필요"))) | U13: =IF(M13="","",IF(M13="-","측정불가",IF(NOT(ISNUMBER(M13)),"확인필요",IF(M13<설정!$C$15,"긴급(저혈당)",IF(M13>=설정!$C$16,"긴급(고혈당)",IF(N13="공복",IF(M13>=설정!$C$13,"주의","정상"),IF(N13="식후",IF(M13>=설정!$C$14,"주의","정상"),"조건확인"))))))) | V13: =IF(OR(T13="긴급",LEFT(U13,2)="긴급",P13="O"),"대상","") | W13: =IF(R13<>"",R13,IF(O13="O",IF(V13="대상",IF(Q13="O","완료","추가상담 대기"),"완료"),IF(COUNTA(K13:M13)=3,"상담 대기",IF(J13="O","측정 대기",IF(I13="O","운동평가 대기","미방문"))))) -> 미방문 | AC13: =IF(AND(ISNUMBER(X13),ISNUMBER(Y13)),IF(Y13>=X13,ROUND((Y13-X13)*1440,0),""),"") | AD13: =IF(AND(ISNUMBER(Y13),ISNUMBER(Z13)),IF(Z13>=Y13,ROUND((Z13-Y13)*1440,0),""),"") | AE13: =IF(AND(ISNUMBER(Z13),ISNUMBER(AA13)),IF(AA13>=Z13,ROUND((AA13-Z13)*1440,0),""),"") | AF13: =IF(AND(ISNUMBER(AA13),ISNUMBER(AB13)),IF(AB13>=AA13,ROUND((AB13-AA13)*1440,0),""),"") | AG13: =IF(AND(W13="완료",ISNUMBER(X13)),IF(MAX(Y13:AB13)>=X13,ROUND((MAX(Y13:AB13)-X13)*1440,0),""),"")
A14: 10 | T14: =IF(AND(K14="",L14=""),"",IF(OR(K14="-",L14="-"),"측정불가",IF(AND(ISNUMBER(K14),ISNUMBER(L14)),IF(OR(K14>=설정!$C$9,L14>=설정!$C$10),"긴급",IF(OR(K14>=설정!$C$7,L14>=설정!$C$8,K14<설정!$C$11),"주의","정상")),"확인필요"))) | U14: =IF(M14="","",IF(M14="-","측정불가",IF(NOT(ISNUMBER(M14)),"확인필요",IF(M14<설정!$C$15,"긴급(저혈당)",IF(M14>=설정!$C$16,"긴급(고혈당)",IF(N14="공복",IF(M14>=설정!$C$13,"주의","정상"),IF(N14="식후",IF(M14>=설정!$C$14,"주의","정상"),"조건확인"))))))) | V14: =IF(OR(T14="긴급",LEFT(U14,2)="긴급",P14="O"),"대상","") | W14: =IF(R14<>"",R14,IF(O14="O",IF(V14="대상",IF(Q14="O","완료","추가상담 대기"),"완료"),IF(COUNTA(K14:M14)=3,"상담 대기",IF(J14="O","측정 대기",IF(I14="O","운동평가 대기","미방문"))))) -> 미방문 | AC14: =IF(AND(ISNUMBER(X14),ISNUMBER(Y14)),IF(Y14>=X14,ROUND((Y14-X14)*1440,0),""),"") | AD14: =IF(AND(ISNUMBER(Y14),ISNUMBER(Z14)),IF(Z14>=Y14,ROUND((Z14-Y14)*1440,0),""),"") | AE14: =IF(AND(ISNUMBER(Z14),ISNUMBER(AA14)),IF(AA14>=Z14,ROUND((AA14-Z14)*1440,0),""),"") | AF14: =IF(AND(ISNUMBER(AA14),ISNUMBER(AB14)),IF(AB14>=AA14,ROUND((AB14-AA14)*1440,0),""),"") | AG14: =IF(AND(W14="완료",ISNUMBER(X14)),IF(MAX(Y14:AB14)>=X14,ROUND((MAX(Y14:AB14)-X14)*1440,0),""),"")
A15: 11 | T15: =IF(AND(K15="",L15=""),"",IF(OR(K15="-",L15="-"),"측정불가",IF(AND(ISNUMBER(K15),ISNUMBER(L15)),IF(OR(K15>=설정!$C$9,L15>=설정!$C$10),"긴급",IF(OR(K15>=설정!$C$7,L15>=설정!$C$8,K15<설정!$C$11),"주의","정상")),"확인필요"))) | U15: =IF(M15="","",IF(M15="-","측정불가",IF(NOT(ISNUMBER(M15)),"확인필요",IF(M15<설정!$C$15,"긴급(저혈당)",IF(M15>=설정!$C$16,"긴급(고혈당)",IF(N15="공복",IF(M15>=설정!$C$13,"주의","정상"),IF(N15="식후",IF(M15>=설정!$C$14,"주의","정상"),"조건확인"))))))) | V15: =IF(OR(T15="긴급",LEFT(U15,2)="긴급",P15="O"),"대상","") | W15: =IF(R15<>"",R15,IF(O15="O",IF(V15="대상",IF(Q15="O","완료","추가상담 대기"),"완료"),IF(COUNTA(K15:M15)=3,"상담 대기",IF(J15="O","측정 대기",IF(I15="O","운동평가 대기","미방문"))))) -> 미방문 | AC15: =IF(AND(ISNUMBER(X15),ISNUMBER(Y15)),IF(Y15>=X15,ROUND((Y15-X15)*1440,0),""),"") | AD15: =IF(AND(ISNUMBER(Y15),ISNUMBER(Z15)),IF(Z15>=Y15,ROUND((Z15-Y15)*1440,0),""),"") | AE15: =IF(AND(ISNUMBER(Z15),ISNUMBER(AA15)),IF(AA15>=Z15,ROUND((AA15-Z15)*1440,0),""),"") | AF15: =IF(AND(ISNUMBER(AA15),ISNUMBER(AB15)),IF(AB15>=AA15,ROUND((AB15-AA15)*1440,0),""),"") | AG15: =IF(AND(W15="완료",ISNUMBER(X15)),IF(MAX(Y15:AB15)>=X15,ROUND((MAX(Y15:AB15)-X15)*1440,0),""),"")
A16: 12 | T16: =IF(AND(K16="",L16=""),"",IF(OR(K16="-",L16="-"),"측정불가",IF(AND(ISNUMBER(K16),ISNUMBER(L16)),IF(OR(K16>=설정!$C$9,L16>=설정!$C$10),"긴급",IF(OR(K16>=설정!$C$7,L16>=설정!$C$8,K16<설정!$C$11),"주의","정상")),"확인필요"))) | U16: =IF(M16="","",IF(M16="-","측정불가",IF(NOT(ISNUMBER(M16)),"확인필요",IF(M16<설정!$C$15,"긴급(저혈당)",IF(M16>=설정!$C$16,"긴급(고혈당)",IF(N16="공복",IF(M16>=설정!$C$13,"주의","정상"),IF(N16="식후",IF(M16>=설정!$C$14,"주의","정상"),"조건확인"))))))) | V16: =IF(OR(T16="긴급",LEFT(U16,2)="긴급",P16="O"),"대상","") | W16: =IF(R16<>"",R16,IF(O16="O",IF(V16="대상",IF(Q16="O","완료","추가상담 대기"),"완료"),IF(COUNTA(K16:M16)=3,"상담 대기",IF(J16="O","측정 대기",IF(I16="O","운동평가 대기","미방문"))))) -> 미방문 | AC16: =IF(AND(ISNUMBER(X16),ISNUMBER(Y16)),IF(Y16>=X16,ROUND((Y16-X16)*1440,0),""),"") | AD16: =IF(AND(ISNUMBER(Y16),ISNUMBER(Z16)),IF(Z16>=Y16,ROUND((Z16-Y16)*1440,0),""),"") | AE16: =IF(AND(ISNUMBER(Z16),ISNUMBER(AA16)),IF(AA16>=Z16,ROUND((AA16-Z16)*1440,0),""),"") | AF16: =IF(AND(ISNUMBER(AA16),ISNUMBER(AB16)),IF(AB16>=AA16,ROUND((AB16-AA16)*1440,0),""),"") | AG16: =IF(AND(W16="완료",ISNUMBER(X16)),IF(MAX(Y16:AB16)>=X16,ROUND((MAX(Y16:AB16)-X16)*1440,0),""),"")
... A404: 400 | T404: =IF(AND(K404="",L404=""),"",IF(OR(K404="-",L404="-"),"측정불가",IF(AND(ISNUMBER(K404),ISNUMBER(L404)),IF(OR(K404>=설정!$C$9,L404>=설정!$C$10),"긴급",IF(OR(K404>=설정!$C$7,L404>=설정!$C$8,K404<설정!$C$11),"주의","정상")),"확인필요"))) | U404: =IF(M404="","",IF(M404="-","측정불가",IF(NOT(ISNUMBER(M404)),"확인필요",IF(M404<설정!$C$15,"긴급(저혈당)",IF(M404>=설정!$C$16,"긴급(고혈당)",IF(N404="공복",IF(M404>=설정!$C$13,"주의","정상"),IF(N404="식후",IF(M404>=설정!$C$14,"주의","정상"),"조건확인"))))))) | V404: =IF(OR(T404="긴급",LEFT(U404,2)="긴급",P404="O"),"대상","") | W404: =IF(R404<>"",R404,IF(O404="O",IF(V404="대상",IF(Q404="O","완료","추가상담 대기"),"완료"),IF(COUNTA(K404:M404)=3,"상담 대기",IF(J404="O","측정 대기",IF(I404="O","운동평가 대기","미방문"))))) -> 미방문 | AC404: =IF(AND(ISNUMBER(X404),ISNUMBER(Y404)),IF(Y404>=X404,ROUND((Y404-X404)*1440,0),""),"") | AD404: =IF(AND(ISNUMBER(Y404),ISNUMBER(Z404)),IF(Z404>=Y404,ROUND((Z404-Y404)*1440,0),""),"") | AE404: =IF(AND(ISNUMBER(Z404),ISNUMBER(AA404)),IF(AA404>=Z404,ROUND((AA404-Z404)*1440,0),""),"") | AF404: =IF(AND(ISNUMBER(AA404),ISNUMBER(AB404)),IF(AB404>=AA404,ROUND((AB404-AA404)*1440,0),""),"") | AG404: =IF(AND(W404="완료",ISNUMBER(X404)),IF(MAX(Y404:AB404)>=X404,ROUND((MAX(Y404:AB404)-X404)*1440,0),""),"")

Sheet 일정표
B1: 일정표 (날짜 × 시간대 예약 인원)
B2: 명단의 예약일·예약시간을 자동 집계합니다. 빨간 칸 = 정원 초과, 노란 칸 = 정원 가득. 날짜·시간·정원은 설정 시트에서 바꿉니다.
D3: =IF(D4="","",CHOOSE(WEEKDAY(D4),"일","월","화","수","목","금","토")) -> 월 | E3: =IF(E4="","",CHOOSE(WEEKDAY(E4),"일","월","화","수","목","금","토")) -> 화 | F3: =IF(F4="","",CHOOSE(WEEKDAY(F4),"일","월","화","수","목","금","토")) -> 수 | G3: =IF(G4="","",CHOOSE(WEEKDAY(G4),"일","월","화","수","목","금","토")) -> 목 | H3: =IF(H4="","",CHOOSE(WEEKDAY(H4),"일","월","화","수","목","금","토")) -> 금 | I3: =IF(I4="","",CHOOSE(WEEKDAY(I4),"일","월","화","수","목","금","토")) -> 월 | J3: =IF(J4="","",CHOOSE(WEEKDAY(J4),"일","월","화","수","목","금","토")) -> 화 | K3: =IF(K4="","",CHOOSE(WEEKDAY(K4),"일","월","화","수","목","금","토")) -> 수 | ... M3: =IF(M4="","",CHOOSE(WEEKDAY(M4),"일","월","화","수","목","금","토")) -> 금
B4: 시작 시각 | C4: 정원 | D4: =IF(설정!$C$19="","",설정!$C$19) -> 46314 | E4: =IF(설정!$C$20="","",설정!$C$20) -> 46315 | F4: =IF(설정!$C$21="","",설정!$C$21) -> 46316 | G4: =IF(설정!$C$22="","",설정!$C$22) -> 46317 | H4: =IF(설정!$C$23="","",설정!$C$23) -> 46318 | I4: =IF(설정!$C$24="","",설정!$C$24) -> 46321 | J4: =IF(설정!$C$25="","",설정!$C$25) -> 46322 | K4: =IF(설정!$C$26="","",설정!$C$26) -> 46323 | L4: =IF(설정!$C$27="","",설정!$C$27) -> 46324 | M4: =IF(설정!$C$28="","",설정!$C$28) -> 46325
B5: =IF(설정!$C$31="","",설정!$C$31) -> 0.375 | C5: =IF(설정!$D$31="","",설정!$D$31) -> 4 | D5: =IF(OR(D$4="",$B5=""),"",COUNTIFS(명단!$F$5:$F$404,D$4,명단!$G$5:$G$404,$B5)) -> 0 | E5: =IF(OR(E$4="",$B5=""),"",COUNTIFS(명단!$F$5:$F$404,E$4,명단!$G$5:$G$404,$B5)) -> 0 | F5: =IF(OR(F$4="",$B5=""),"",COUNTIFS(명단!$F$5:$F$404,F$4,명단!$G$5:$G$404,$B5)) -> 0 | G5: =IF(OR(G$4="",$B5=""),"",COUNTIFS(명단!$F$5:$F$404,G$4,명단!$G$5:$G$404,$B5)) -> 0 | H5: =IF(OR(H$4="",$B5=""),"",COUNTIFS(명단!$F$5:$F$404,H$4,명단!$G$5:$G$404,$B5)) -> 0 | I5: =IF(OR(I$4="",$B5=""),"",COUNTIFS(명단!$F$5:$F$404,I$4,명단!$G$5:$G$404,$B5)) -> 0 | J5: =IF(OR(J$4="",$B5=""),"",COUNTIFS(명단!$F$5:$F$404,J$4,명단!$G$5:$G$404,$B5)) -> 0 | K5: =IF(OR(K$4="",$B5=""),"",COUNTIFS(명단!$F$5:$F$404,K$4,명단!$G$5:$G$404,$B5)) -> 0 | ... M5: =IF(OR(M$4="",$B5=""),"",COUNTIFS(명단!$F$5:$F$404,M$4,명단!$G$5:$G$404,$B5)) -> 0
B6: =IF(설정!$C$32="","",설정!$C$32) -> 0.39583333 | C6: =IF(설정!$D$32="","",설정!$D$32) -> 4 | D6: =IF(OR(D$4="",$B6=""),"",COUNTIFS(명단!$F$5:$F$404,D$4,명단!$G$5:$G$404,$B6)) -> 0 | E6: =IF(OR(E$4="",$B6=""),"",COUNTIFS(명단!$F$5:$F$404,E$4,명단!$G$5:$G$404,$B6)) -> 0 | F6: =IF(OR(F$4="",$B6=""),"",COUNTIFS(명단!$F$5:$F$404,F$4,명단!$G$5:$G$404,$B6)) -> 0 | G6: =IF(OR(G$4="",$B6=""),"",COUNTIFS(명단!$F$5:$F$404,G$4,명단!$G$5:$G$404,$B6)) -> 0 | H6: =IF(OR(H$4="",$B6=""),"",COUNTIFS(명단!$F$5:$F$404,H$4,명단!$G$5:$G$404,$B6)) -> 0 | I6: =IF(OR(I$4="",$B6=""),"",COUNTIFS(명단!$F$5:$F$404,I$4,명단!$G$5:$G$404,$B6)) -> 0 | J6: =IF(OR(J$4="",$B6=""),"",COUNTIFS(명단!$F$5:$F$404,J$4,명단!$G$5:$G$404,$B6)) -> 0 | K6: =IF(OR(K$4="",$B6=""),"",COUNTIFS(명단!$F$5:$F$404,K$4,명단!$G$5:$G$404,$B6)) -> 0 | ... M6: =IF(OR(M$4="",$B6=""),"",COUNTIFS(명단!$F$5:$F$404,M$4,명단!$G$5:$G$404,$B6)) -> 0
B7: =IF(설정!$C$33="","",설정!$C$33) -> 0.41666667 | C7: =IF(설정!$D$33="","",설정!$D$33) -> 4 | D7: =IF(OR(D$4="",$B7=""),"",COUNTIFS(명단!$F$5:$F$404,D$4,명단!$G$5:$G$404,$B7)) -> 0 | E7: =IF(OR(E$4="",$B7=""),"",COUNTIFS(명단!$F$5:$F$404,E$4,명단!$G$5:$G$404,$B7)) -> 0 | F7: =IF(OR(F$4="",$B7=""),"",COUNTIFS(명단!$F$5:$F$404,F$4,명단!$G$5:$G$404,$B7)) -> 0 | G7: =IF(OR(G$4="",$B7=""),"",COUNTIFS(명단!$F$5:$F$404,G$4,명단!$G$5:$G$404,$B7)) -> 0 | H7: =IF(OR(H$4="",$B7=""),"",COUNTIFS(명단!$F$5:$F$404,H$4,명단!$G$5:$G$404,$B7)) -> 0 | I7: =IF(OR(I$4="",$B7=""),"",COUNTIFS(명단!$F$5:$F$404,I$4,명단!$G$5:$G$404,$B7)) -> 0 | J7: =IF(OR(J$4="",$B7=""),"",COUNTIFS(명단!$F$5:$F$404,J$4,명단!$G$5:$G$404,$B7)) -> 0 | K7: =IF(OR(K$4="",$B7=""),"",COUNTIFS(명단!$F$5:$F$404,K$4,명단!$G$5:$G$404,$B7)) -> 0 | ... M7: =IF(OR(M$4="",$B7=""),"",COUNTIFS(명단!$F$5:$F$404,M$4,명단!$G$5:$G$404,$B7)) -> 0
B8: =IF(설정!$C$34="","",설정!$C$34) -> 0.4375 | C8: =IF(설정!$D$34="","",설정!$D$34) -> 4 | D8: =IF(OR(D$4="",$B8=""),"",COUNTIFS(명단!$F$5:$F$404,D$4,명단!$G$5:$G$404,$B8)) -> 0 | E8: =IF(OR(E$4="",$B8=""),"",COUNTIFS(명단!$F$5:$F$404,E$4,명단!$G$5:$G$404,$B8)) -> 0 | F8: =IF(OR(F$4="",$B8=""),"",COUNTIFS(명단!$F$5:$F$404,F$4,명단!$G$5:$G$404,$B8)) -> 0 | G8: =IF(OR(G$4="",$B8=""),"",COUNTIFS(명단!$F$5:$F$404,G$4,명단!$G$5:$G$404,$B8)) -> 0 | H8: =IF(OR(H$4="",$B8=""),"",COUNTIFS(명단!$F$5:$F$404,H$4,명단!$G$5:$G$404,$B8)) -> 0 | I8: =IF(OR(I$4="",$B8=""),"",COUNTIFS(명단!$F$5:$F$404,I$4,명단!$G$5:$G$404,$B8)) -> 0 | J8: =IF(OR(J$4="",$B8=""),"",COUNTIFS(명단!$F$5:$F$404,J$4,명단!$G$5:$G$404,$B8)) -> 0 | K8: =IF(OR(K$4="",$B8=""),"",COUNTIFS(명단!$F$5:$F$404,K$4,명단!$G$5:$G$404,$B8)) -> 0 | ... M8: =IF(OR(M$4="",$B8=""),"",COUNTIFS(명단!$F$5:$F$404,M$4,명단!$G$5:$G$404,$B8)) -> 0
B9: =IF(설정!$C$35="","",설정!$C$35) -> 0.45833333 | C9: =IF(설정!$D$35="","",설정!$D$35) -> 4 | D9: =IF(OR(D$4="",$B9=""),"",COUNTIFS(명단!$F$5:$F$404,D$4,명단!$G$5:$G$404,$B9)) -> 0 | E9: =IF(OR(E$4="",$B9=""),"",COUNTIFS(명단!$F$5:$F$404,E$4,명단!$G$5:$G$404,$B9)) -> 0 | F9: =IF(OR(F$4="",$B9=""),"",COUNTIFS(명단!$F$5:$F$404,F$4,명단!$G$5:$G$404,$B9)) -> 0 | G9: =IF(OR(G$4="",$B9=""),"",COUNTIFS(명단!$F$5:$F$404,G$4,명단!$G$5:$G$404,$B9)) -> 0 | H9: =IF(OR(H$4="",$B9=""),"",COUNTIFS(명단!$F$5:$F$404,H$4,명단!$G$5:$G$404,$B9)) -> 0 | I9: =IF(OR(I$4="",$B9=""),"",COUNTIFS(명단!$F$5:$F$404,I$4,명단!$G$5:$G$404,$B9)) -> 0 | J9: =IF(OR(J$4="",$B9=""),"",COUNTIFS(명단!$F$5:$F$404,J$4,명단!$G$5:$G$404,$B9)) -> 0 | K9: =IF(OR(K$4="",$B9=""),"",COUNTIFS(명단!$F$5:$F$404,K$4,명단!$G$5:$G$404,$B9)) -> 0 | ... M9: =IF(OR(M$4="",$B9=""),"",COUNTIFS(명단!$F$5:$F$404,M$4,명단!$G$5:$G$404,$B9)) -> 0
B10: =IF(설정!$C$36="","",설정!$C$36) -> 0.47916667 | C10: =IF(설정!$D$36="","",설정!$D$36) -> 4 | D10: =IF(OR(D$4="",$B10=""),"",COUNTIFS(명단!$F$5:$F$404,D$4,명단!$G$5:$G$404,$B10)) -> 0 | E10: =IF(OR(E$4="",$B10=""),"",COUNTIFS(명단!$F$5:$F$404,E$4,명단!$G$5:$G$404,$B10)) -> 0 | F10: =IF(OR(F$4="",$B10=""),"",COUNTIFS(명단!$F$5:$F$404,F$4,명단!$G$5:$G$404,$B10)) -> 0 | G10: =IF(OR(G$4="",$B10=""),"",COUNTIFS(명단!$F$5:$F$404,G$4,명단!$G$5:$G$404,$B10)) -> 0 | H10: =IF(OR(H$4="",$B10=""),"",COUNTIFS(명단!$F$5:$F$404,H$4,명단!$G$5:$G$404,$B10)) -> 0 | I10: =IF(OR(I$4="",$B10=""),"",COUNTIFS(명단!$F$5:$F$404,I$4,명단!$G$5:$G$404,$B10)) -> 0 | J10: =IF(OR(J$4="",$B10=""),"",COUNTIFS(명단!$F$5:$F$404,J$4,명단!$G$5:$G$404,$B10)) -> 0 | K10: =IF(OR(K$4="",$B10=""),"",COUNTIFS(명단!$F$5:$F$404,K$4,명단!$G$5:$G$404,$B10)) -> 0 | ... M10: =IF(OR(M$4="",$B10=""),"",COUNTIFS(명단!$F$5:$F$404,M$4,명단!$G$5:$G$404,$B10)) -> 0
B11: =IF(설정!$C$37="","",설정!$C$37) -> 0.5625 | C11: =IF(설정!$D$37="","",설정!$D$37) -> 4 | D11: =IF(OR(D$4="",$B11=""),"",COUNTIFS(명단!$F$5:$F$404,D$4,명단!$G$5:$G$404,$B11)) -> 0 | E11: =IF(OR(E$4="",$B11=""),"",COUNTIFS(명단!$F$5:$F$404,E$4,명단!$G$5:$G$404,$B11)) -> 0 | F11: =IF(OR(F$4="",$B11=""),"",COUNTIFS(명단!$F$5:$F$404,F$4,명단!$G$5:$G$404,$B11)) -> 0 | G11: =IF(OR(G$4="",$B11=""),"",COUNTIFS(명단!$F$5:$F$404,G$4,명단!$G$5:$G$404,$B11)) -> 0 | H11: =IF(OR(H$4="",$B11=""),"",COUNTIFS(명단!$F$5:$F$404,H$4,명단!$G$5:$G$404,$B11)) -> 0 | I11: =IF(OR(I$4="",$B11=""),"",COUNTIFS(명단!$F$5:$F$404,I$4,명단!$G$5:$G$404,$B11)) -> 0 | J11: =IF(OR(J$4="",$B11=""),"",COUNTIFS(명단!$F$5:$F$404,J$4,명단!$G$5:$G$404,$B11)) -> 0 | K11: =IF(OR(K$4="",$B11=""),"",COUNTIFS(명단!$F$5:$F$404,K$4,명단!$G$5:$G$404,$B11)) -> 0 | ... M11: =IF(OR(M$4="",$B11=""),"",COUNTIFS(명단!$F$5:$F$404,M$4,명단!$G$5:$G$404,$B11)) -> 0
B12: =IF(설정!$C$38="","",설정!$C$38) -> 0.58333333 | C12: =IF(설정!$D$38="","",설정!$D$38) -> 4 | D12: =IF(OR(D$4="",$B12=""),"",COUNTIFS(명단!$F$5:$F$404,D$4,명단!$G$5:$G$404,$B12)) -> 0 | E12: =IF(OR(E$4="",$B12=""),"",COUNTIFS(명단!$F$5:$F$404,E$4,명단!$G$5:$G$404,$B12)) -> 0 | F12: =IF(OR(F$4="",$B12=""),"",COUNTIFS(명단!$F$5:$F$404,F$4,명단!$G$5:$G$404,$B12)) -> 0 | G12: =IF(OR(G$4="",$B12=""),"",COUNTIFS(명단!$F$5:$F$404,G$4,명단!$G$5:$G$404,$B12)) -> 0 | H12: =IF(OR(H$4="",$B12=""),"",COUNTIFS(명단!$F$5:$F$404,H$4,명단!$G$5:$G$404,$B12)) -> 0 | I12: =IF(OR(I$4="",$B12=""),"",COUNTIFS(명단!$F$5:$F$404,I$4,명단!$G$5:$G$404,$B12)) -> 0 | J12: =IF(OR(J$4="",$B12=""),"",COUNTIFS(명단!$F$5:$F$404,J$4,명단!$G$5:$G$404,$B12)) -> 0 | K12: =IF(OR(K$4="",$B12=""),"",COUNTIFS(명단!$F$5:$F$404,K$4,명단!$G$5:$G$404,$B12)) -> 0 | ... M12: =IF(OR(M$4="",$B12=""),"",COUNTIFS(명단!$F$5:$F$404,M$4,명단!$G$5:$G$404,$B12)) -> 0
B13: =IF(설정!$C$39="","",설정!$C$39) -> 0.60416667 | C13: =IF(설정!$D$39="","",설정!$D$39) -> 4 | D13: =IF(OR(D$4="",$B13=""),"",COUNTIFS(명단!$F$5:$F$404,D$4,명단!$G$5:$G$404,$B13)) -> 0 | E13: =IF(OR(E$4="",$B13=""),"",COUNTIFS(명단!$F$5:$F$404,E$4,명단!$G$5:$G$404,$B13)) -> 0 | F13: =IF(OR(F$4="",$B13=""),"",COUNTIFS(명단!$F$5:$F$404,F$4,명단!$G$5:$G$404,$B13)) -> 0 | G13: =IF(OR(G$4="",$B13=""),"",COUNTIFS(명단!$F$5:$F$404,G$4,명단!$G$5:$G$404,$B13)) -> 0 | H13: =IF(OR(H$4="",$B13=""),"",COUNTIFS(명단!$F$5:$F$404,H$4,명단!$G$5:$G$404,$B13)) -> 0 | I13: =IF(OR(I$4="",$B13=""),"",COUNTIFS(명단!$F$5:$F$404,I$4,명단!$G$5:$G$404,$B13)) -> 0 | J13: =IF(OR(J$4="",$B13=""),"",COUNTIFS(명단!$F$5:$F$404,J$4,명단!$G$5:$G$404,$B13)) -> 0 | K13: =IF(OR(K$4="",$B13=""),"",COUNTIFS(명단!$F$5:$F$404,K$4,명단!$G$5:$G$404,$B13)) -> 0 | ... M13: =IF(OR(M$4="",$B13=""),"",COUNTIFS(명단!$F$5:$F$404,M$4,명단!$G$5:$G$404,$B13)) -> 0
B14: =IF(설정!$C$40="","",설정!$C$40) -> 0.625 | C14: =IF(설정!$D$40="","",설정!$D$40) -> 4 | D14: =IF(OR(D$4="",$B14=""),"",COUNTIFS(명단!$F$5:$F$404,D$4,명단!$G$5:$G$404,$B14)) -> 0 | E14: =IF(OR(E$4="",$B14=""),"",COUNTIFS(명단!$F$5:$F$404,E$4,명단!$G$5:$G$404,$B14)) -> 0 | F14: =IF(OR(F$4="",$B14=""),"",COUNTIFS(명단!$F$5:$F$404,F$4,명단!$G$5:$G$404,$B14)) -> 0 | G14: =IF(OR(G$4="",$B14=""),"",COUNTIFS(명단!$F$5:$F$404,G$4,명단!$G$5:$G$404,$B14)) -> 0 | H14: =IF(OR(H$4="",$B14=""),"",COUNTIFS(명단!$F$5:$F$404,H$4,명단!$G$5:$G$404,$B14)) -> 0 | I14: =IF(OR(I$4="",$B14=""),"",COUNTIFS(명단!$F$5:$F$404,I$4,명단!$G$5:$G$404,$B14)) -> 0 | J14: =IF(OR(J$4="",$B14=""),"",COUNTIFS(명단!$F$5:$F$404,J$4,명단!$G$5:$G$404,$B14)) -> 0 | K14: =IF(OR(K$4="",$B14=""),"",COUNTIFS(명단!$F$5:$F$404,K$4,명단!$G$5:$G$404,$B14)) -> 0 | ... M14: =IF(OR(M$4="",$B14=""),"",COUNTIFS(명단!$F$5:$F$404,M$4,명단!$G$5:$G$404,$B14)) -> 0
B15: =IF(설정!$C$41="","",설정!$C$41) -> 0.64583333 | C15: =IF(설정!$D$41="","",설정!$D$41) -> 4 | D15: =IF(OR(D$4="",$B15=""),"",COUNTIFS(명단!$F$5:$F$404,D$4,명단!$G$5:$G$404,$B15)) -> 0 | E15: =IF(OR(E$4="",$B15=""),"",COUNTIFS(명단!$F$5:$F$404,E$4,명단!$G$5:$G$404,$B15)) -> 0 | F15: =IF(OR(F$4="",$B15=""),"",COUNTIFS(명단!$F$5:$F$404,F$4,명단!$G$5:$G$404,$B15)) -> 0 | G15: =IF(OR(G$4="",$B15=""),"",COUNTIFS(명단!$F$5:$F$404,G$4,명단!$G$5:$G$404,$B15)) -> 0 | H15: =IF(OR(H$4="",$B15=""),"",COUNTIFS(명단!$F$5:$F$404,H$4,명단!$G$5:$G$404,$B15)) -> 0 | I15: =IF(OR(I$4="",$B15=""),"",COUNTIFS(명단!$F$5:$F$404,I$4,명단!$G$5:$G$404,$B15)) -> 0 | J15: =IF(OR(J$4="",$B15=""),"",COUNTIFS(명단!$F$5:$F$404,J$4,명단!$G$5:$G$404,$B15)) -> 0 | K15: =IF(OR(K$4="",$B15=""),"",COUNTIFS(명단!$F$5:$F$404,K$4,명단!$G$5:$G$404,$B15)) -> 0 | ... M15: =IF(OR(M$4="",$B15=""),"",COUNTIFS(명단!$F$5:$F$404,M$4,명단!$G$5:$G$404,$B15)) -> 0
B16: =IF(설정!$C$42="","",설정!$C$42) -> 0.66666667 | C16: =IF(설정!$D$42="","",설정!$D$42) -> 4 | D16: =IF(OR(D$4="",$B16=""),"",COUNTIFS(명단!$F$5:$F$404,D$4,명단!$G$5:$G$404,$B16)) -> 0 | E16: =IF(OR(E$4="",$B16=""),"",COUNTIFS(명단!$F$5:$F$404,E$4,명단!$G$5:$G$404,$B16)) -> 0 | F16: =IF(OR(F$4="",$B16=""),"",COUNTIFS(명단!$F$5:$F$404,F$4,명단!$G$5:$G$404,$B16)) -> 0 | G16: =IF(OR(G$4="",$B16=""),"",COUNTIFS(명단!$F$5:$F$404,G$4,명단!$G$5:$G$404,$B16)) -> 0 | H16: =IF(OR(H$4="",$B16=""),"",COUNTIFS(명단!$F$5:$F$404,H$4,명단!$G$5:$G$404,$B16)) -> 0 | I16: =IF(OR(I$4="",$B16=""),"",COUNTIFS(명단!$F$5:$F$404,I$4,명단!$G$5:$G$404,$B16)) -> 0 | J16: =IF(OR(J$4="",$B16=""),"",COUNTIFS(명단!$F$5:$F$404,J$4,명단!$G$5:$G$404,$B16)) -> 0 | K16: =IF(OR(K$4="",$B16=""),"",COUNTIFS(명단!$F$5:$F$404,K$4,명단!$G$5:$G$404,$B16)) -> 0 | ... M16: =IF(OR(M$4="",$B16=""),"",COUNTIFS(명단!$F$5:$F$404,M$4,명단!$G$5:$G$404,$B16)) -> 0
B17: 시간 미지정 | D17: =IF(D$4="","",COUNTIFS(명단!$F$5:$F$404,D$4,명단!$G$5:$G$404,"")) -> 0 | E17: =IF(E$4="","",COUNTIFS(명단!$F$5:$F$404,E$4,명단!$G$5:$G$404,"")) -> 0 | F17: =IF(F$4="","",COUNTIFS(명단!$F$5:$F$404,F$4,명단!$G$5:$G$404,"")) -> 0 | G17: =IF(G$4="","",COUNTIFS(명단!$F$5:$F$404,G$4,명단!$G$5:$G$404,"")) -> 0 | H17: =IF(H$4="","",COUNTIFS(명단!$F$5:$F$404,H$4,명단!$G$5:$G$404,"")) -> 0 | I17: =IF(I$4="","",COUNTIFS(명단!$F$5:$F$404,I$4,명단!$G$5:$G$404,"")) -> 0 | J17: =IF(J$4="","",COUNTIFS(명단!$F$5:$F$404,J$4,명단!$G$5:$G$404,"")) -> 0 | K17: =IF(K$4="","",COUNTIFS(명단!$F$5:$F$404,K$4,명단!$G$5:$G$404,"")) -> 0 | ... M17: =IF(M$4="","",COUNTIFS(명단!$F$5:$F$404,M$4,명단!$G$5:$G$404,"")) -> 0
B18: 예약 합계 | D18: =IF(D$4="","",COUNTIFS(명단!$F$5:$F$404,D$4)) -> 0 | E18: =IF(E$4="","",COUNTIFS(명단!$F$5:$F$404,E$4)) -> 0 | F18: =IF(F$4="","",COUNTIFS(명단!$F$5:$F$404,F$4)) -> 0 | G18: =IF(G$4="","",COUNTIFS(명단!$F$5:$F$404,G$4)) -> 0 | H18: =IF(H$4="","",COUNTIFS(명단!$F$5:$F$404,H$4)) -> 0 | I18: =IF(I$4="","",COUNTIFS(명단!$F$5:$F$404,I$4)) -> 0 | J18: =IF(J$4="","",COUNTIFS(명단!$F$5:$F$404,J$4)) -> 0 | K18: =IF(K$4="","",COUNTIFS(명단!$F$5:$F$404,K$4)) -> 0 | ... M18: =IF(M$4="","",COUNTIFS(명단!$F$5:$F$404,M$4)) -> 0
B19: 하루 정원 합계 | D19: =IF(D$4="","",SUM($C$5:$C$16)) -> 48 | E19: =IF(E$4="","",SUM($C$5:$C$16)) -> 48 | F19: =IF(F$4="","",SUM($C$5:$C$16)) -> 48 | G19: =IF(G$4="","",SUM($C$5:$C$16)) -> 48 | H19: =IF(H$4="","",SUM($C$5:$C$16)) -> 48 | I19: =IF(I$4="","",SUM($C$5:$C$16)) -> 48 | J19: =IF(J$4="","",SUM($C$5:$C$16)) -> 48 | K19: =IF(K$4="","",SUM($C$5:$C$16)) -> 48 | ... M19: =IF(M$4="","",SUM($C$5:$C$16)) -> 48
B20: 완료 | D20: =IF(D$4="","",COUNTIFS(명단!$F$5:$F$404,D$4,명단!$W$5:$W$404,"완료")) -> 0 | E20: =IF(E$4="","",COUNTIFS(명단!$F$5:$F$404,E$4,명단!$W$5:$W$404,"완료")) -> 0 | F20: =IF(F$4="","",COUNTIFS(명단!$F$5:$F$404,F$4,명단!$W$5:$W$404,"완료")) -> 0 | G20: =IF(G$4="","",COUNTIFS(명단!$F$5:$F$404,G$4,명단!$W$5:$W$404,"완료")) -> 0 | H20: =IF(H$4="","",COUNTIFS(명단!$F$5:$F$404,H$4,명단!$W$5:$W$404,"완료")) -> 0 | I20: =IF(I$4="","",COUNTIFS(명단!$F$5:$F$404,I$4,명단!$W$5:$W$404,"완료")) -> 0 | J20: =IF(J$4="","",COUNTIFS(명단!$F$5:$F$404,J$4,명단!$W$5:$W$404,"완료")) -> 0 | K20: =IF(K$4="","",COUNTIFS(명단!$F$5:$F$404,K$4,명단!$W$5:$W$404,"완료")) -> 0 | ... M20: =IF(M$4="","",COUNTIFS(명단!$F$5:$F$404,M$4,명단!$W$5:$W$404,"완료")) -> 0
B21: 불참·연기 | D21: =IF(D$4="","",COUNTIFS(명단!$F$5:$F$404,D$4,명단!$W$5:$W$404,"불참")+COUNTIFS(명단!$F$5:$F$404,D$4,명단!$W$5:$W$404,"연기")) -> 0 | E21: =IF(E$4="","",COUNTIFS(명단!$F$5:$F$404,E$4,명단!$W$5:$W$404,"불참")+COUNTIFS(명단!$F$5:$F$404,E$4,명단!$W$5:$W$404,"연기")) -> 0 | F21: =IF(F$4="","",COUNTIFS(명단!$F$5:$F$404,F$4,명단!$W$5:$W$404,"불참")+COUNTIFS(명단!$F$5:$F$404,F$4,명단!$W$5:$W$404,"연기")) -> 0 | G21: =IF(G$4="","",COUNTIFS(명단!$F$5:$F$404,G$4,명단!$W$5:$W$404,"불참")+COUNTIFS(명단!$F$5:$F$404,G$4,명단!$W$5:$W$404,"연기")) -> 0 | H21: =IF(H$4="","",COUNTIFS(명단!$F$5:$F$404,H$4,명단!$W$5:$W$404,"불참")+COUNTIFS(명단!$F$5:$F$404,H$4,명단!$W$5:$W$404,"연기")) -> 0 | I21: =IF(I$4="","",COUNTIFS(명단!$F$5:$F$404,I$4,명단!$W$5:$W$404,"불참")+COUNTIFS(명단!$F$5:$F$404,I$4,명단!$W$5:$W$404,"연기")) -> 0 | J21: =IF(J$4="","",COUNTIFS(명단!$F$5:$F$404,J$4,명단!$W$5:$W$404,"불참")+COUNTIFS(명단!$F$5:$F$404,J$4,명단!$W$5:$W$404,"연기")) -> 0 | K21: =IF(K$4="","",COUNTIFS(명단!$F$5:$F$404,K$4,명단!$W$5:$W$404,"불참")+COUNTIFS(명단!$F$5:$F$404,K$4,명단!$W$5:$W$404,"연기")) -> 0 | ... M21: =IF(M$4="","",COUNTIFS(명단!$F$5:$F$404,M$4,명단!$W$5:$W$404,"불참")+COUNTIFS(명단!$F$5:$F$404,M$4,명단!$W$5:$W$404,"연기")) -> 0
B22: 미완료(남은 인원) | D22: =IF(D$4="","",D18-D20-D21) -> 0 | E22: =IF(E$4="","",E18-E20-E21) -> 0 | F22: =IF(F$4="","",F18-F20-F21) -> 0 | G22: =IF(G$4="","",G18-G20-G21) -> 0 | H22: =IF(H$4="","",H18-H20-H21) -> 0 | I22: =IF(I$4="","",I18-I20-I21) -> 0 | J22: =IF(J$4="","",J18-J20-J21) -> 0 | K22: =IF(K$4="","",K18-K20-K21) -> 0 | ... M22: =IF(M$4="","",M18-M20-M21) -> 0
B23: 완료율 | D23: =IF(D$4="","",IF(D18=0,"-",D20/D18)) -> - | E23: =IF(E$4="","",IF(E18=0,"-",E20/E18)) -> - | F23: =IF(F$4="","",IF(F18=0,"-",F20/F18)) -> - | G23: =IF(G$4="","",IF(G18=0,"-",G20/G18)) -> - | H23: =IF(H$4="","",IF(H18=0,"-",H20/H18)) -> - | I23: =IF(I$4="","",IF(I18=0,"-",I20/I18)) -> - | J23: =IF(J$4="","",IF(J18=0,"-",J20/J18)) -> - | K23: =IF(K$4="","",IF(K18=0,"-",K20/K18)) -> - | ... M23: =IF(M$4="","",IF(M18=0,"-",M20/M18)) -> -
B24: 차트용 날짜 | D24: =IF(D$4="","",TEXT(D$4,"m/d")) -> 10/19 | E24: =IF(E$4="","",TEXT(E$4,"m/d")) -> 10/20 | F24: =IF(F$4="","",TEXT(F$4,"m/d")) -> 10/21 | G24: =IF(G$4="","",TEXT(G$4,"m/d")) -> 10/22 | H24: =IF(H$4="","",TEXT(H$4,"m/d")) -> 10/23 | I24: =IF(I$4="","",TEXT(I$4,"m/d")) -> 10/26 | J24: =IF(J$4="","",TEXT(J$4,"m/d")) -> 10/27 | K24: =IF(K$4="","",TEXT(K$4,"m/d")) -> 10/28 | ... M24: =IF(M$4="","",TEXT(M$4,"m/d")) -> 10/30
B25: ※ 정원 합계가 하루 목표 인원보다 작으면 슬롯·정원을 늘리거나 운영일을 추가하세요.

Sheet 병목계산
B1: 병목 계산기 (하루에 몇 명까지 처리 가능한가?)
B2: 노란 칸을 실제 값으로 바꾸세요. 아래 숫자는 모두 '예시값'입니다(운동평가 1명이 15분씩 보는 상황 가정).
B3: 하루 운영 시간(시간) | C3: 5
B4: 목표 인원(명) | C4: =설정!C4 -> 350
B5: 총 운영일 수(일) | C5: =COUNT(설정!C19:C28) -> 10
B6: 예비일(보충 방문용, 일) | C6: 2 | E6: ※ 불참·재방문에 대비해 마지막 1~2일은 보충일로 비워 두는 것을 권장합니다.
B7: 본 일정 일수(일) | C7: =C5-C6 -> 8
B8: 하루 목표 인원(명) | C8: =IF(C7<=0,"-",ROUNDUP(C4/C7,0)) -> 44
B10: 단계 | C10: 1인당 소요(분) | D10: 담당 인원(명) | E10: 이 단계를 거치는 비율 | F10: 시간당 처리 가능(명) | G10: 하루 처리 가능(명) | H10: 목표 달성에 필요한 인원(명)
B11: 운동평가 | C11: 15 | D11: 1 | E11: 1 | F11: =D11*60/C11/E11 -> 4 | G11: =F11*$C$3 -> 20 | H11: =IF(ISNUMBER($C$8),ROUNDUP($C$8*E11*C11/60/$C$3,0),"-") -> 3
B12: 혈압·혈당 측정 | C12: 8 | D12: 2 | E12: 1 | F12: =D12*60/C12/E12 -> 15 | G12: =F12*$C$3 -> 75 | H12: =IF(ISNUMBER($C$8),ROUNDUP($C$8*E12*C12/60/$C$3,0),"-") -> 2
B13: 선생님 상담 | C13: 10 | D13: 3 | E13: 1 | F13: =D13*60/C13/E13 -> 18 | G13: =F13*$C$3 -> 90 | H13: =IF(ISNUMBER($C$8),ROUNDUP($C$8*E13*C13/60/$C$3,0),"-") -> 2
B14: 추가상담 | C14: 15 | D14: 2 | E14: 0.2 | F14: =D14*60/C14/E14 -> 40 | G14: =F14*$C$3 -> 200 | H14: =IF(ISNUMBER($C$8),ROUNDUP($C$8*E14*C14/60/$C$3,0),"-") -> 1
B15: ※ 추가상담은 전체 중 일부(예: 20%)만 거치므로 '비율'을 입력하세요. 상담이 분야별 부스로 나뉘면 부스 수를 담당 인원에 합산하세요.
B17: 결과
B18: 병목 단계(가장 느린 곳) | C18: =INDEX(B11:B14,MATCH(MIN(F11:F14),F11:F14,0)) -> 운동평가
B19: 전체 처리 속도(명/시간) | C19: =MIN(F11:F14) -> 4
B20: 하루 최대 처리(명) | C20: =C19*C3 -> 20
B21: 목표 달성에 필요한 본 일정 일수(일) | C21: =ROUNDUP(C4/C20,0) -> 18
B22: 판정 | C22: =IF(C21<=C7,"가능 ("&C7&"일 이내)","부족: "&C18&" 인력을 늘리거나 운영일·시간 확대 필요") -> 부족: 운동평가 인력을 늘리거나 운영일·시간 확대 필요
B24: 읽는 법: 병목 단계의 '시간당 처리 가능'이 전체 속도를 결정합니다. 목표 달성에 필요한 인원(H열)보다 담당 인원(D열)이 적은 단계에 사람을 더 배치하세요.

Sheet 설정
B2: 설정 (노란 칸만 수정하세요)
B3: 파란 글씨 + 노란 칸 = 직접 입력하는 값. 아래 숫자는 모두 '예시값'이므로 실제 값으로 바꾸세요.
B4: 목표 인원(명) | C4: 350 | E4: 사용자 제공: 2주간 350명 방문 예정
B6: 혈압 판정 기준 (mmHg)
B7: 수축기 '주의' (이상) | C7: 140 | E7: 일반적으로 쓰는 고혈압 진단 기준(140/90)을 예시로 사용
B8: 이완기 '주의' (이상) | C8: 90
B9: 수축기 '긴급' (이상) | C9: 180 | E9: 즉시 선생님 호출·운동 중단 판단용 예시값
B10: 이완기 '긴급' (이상) | C10: 110
B11: 수축기 저혈압 '주의' (미만) | C11: 90 | E11: 어지럼 확인용 예시값
B12: 혈당 판정 기준 (mg/dL)
B13: 공복 '주의' (이상) | C13: 126 | E13: 공복혈당 126 이상(당뇨 진단 기준)을 예시로 사용
B14: 식후 '주의' (이상) | C14: 200 | E14: 식후/무작위 혈당 200 이상을 예시로 사용
B15: 저혈당 '긴급' (미만) | C15: 70 | E15: 즉시 당 섭취·선생님 호출용 예시값
B16: 고혈당 '긴급' (이상) | C16: 300 | E16: 예시값
B17: ※ 위 기준은 예시입니다. 반드시 기관 프로토콜·지도 선생님(간호교수)과 확인한 뒤 수정하세요.
B18: 운영일 (일차) | C18: 날짜
B19: 1일차 | C19: 46314 | E19: 예시: 2026-10-19(월) 시작 평일 10일. 실제 운영일로 바꾸세요. 일수가 다르면 남는 칸은 비워 두세요.
B20: 2일차 | C20: 46315
B21: 3일차 | C21: 46316
B22: 4일차 | C22: 46317
B23: 5일차 | C23: 46318
B24: 6일차 | C24: 46321
B25: 7일차 | C25: 46322
B26: 8일차 | C26: 46323
B27: 9일차 | C27: 46324
B28: 10일차 | C28: 46325
B30: 시간대 슬롯 | C30: 시작 시각 | D30: 정원(명)
B31: 슬롯 1 | C31: 0.375 | D31: 4 | E31: 예시: 30분 간격 12슬롯, 슬롯당 4명. 병목계산 시트 결과(하루 처리 가능 인원)에 맞춰 정원을 조정하세요.
B32: 슬롯 2 | C32: 0.39583333 | D32: 4 | E32: 점심시간 등 쉬는 구간은 슬롯 시각을 비우면 됩니다(정원 칸도 비우세요).
B33: 슬롯 3 | C33: 0.41666667 | D33: 4
B34: 슬롯 4 | C34: 0.4375 | D34: 4
B35: 슬롯 5 | C35: 0.45833333 | D35: 4
B36: 슬롯 6 | C36: 0.47916667 | D36: 4
B37: 슬롯 7 | C37: 0.5625 | D37: 4
B38: 슬롯 8 | C38: 0.58333333 | D38: 4
B39: 슬롯 9 | C39: 0.60416667 | D39: 4
B40: 슬롯 10 | C40: 0.625 | D40: 4
B41: 슬롯 11 | C41: 0.64583333 | D41: 4
B42: 슬롯 12 | C42: 0.66666667 | D42: 4
